<robot name="research_wheeled_y_up">
  <link name="base">
    <collision>
      <geometry>
        <box size="1 0.2 0.5" />
      </geometry>
    </collision>
  </link>

  <link name="left_wheel">
    <collision>
      <geometry>
        <cylinder radius="0.1" length="0.05" />
      </geometry>
    </collision>
  </link>

  <link name="right_wheel">
    <collision>
      <geometry>
        <cylinder radius="0.1" length="0.05" />
      </geometry>
    </collision>
  </link>

  <joint name="left_wheel_joint" type="continuous">
    <parent link="base" />
    <child link="left_wheel" />
    <origin xyz="0 -0.1 0.3" rpy="0 0 0" />
    <axis xyz="0 0 1" />
  </joint>

  <joint name="right_wheel_joint" type="continuous">
    <parent link="base" />
    <child link="right_wheel" />
    <origin xyz="0 -0.1 -0.3" rpy="0 0 0" />
    <axis xyz="0 0 1" />
  </joint>
</robot>
