<robot name="research_wheeled_z_up">
  <link name="base">
    <collision>
      <geometry>
        <box size="1 0.4 0.2" />
      </geometry>
    </collision>
  </link>

  <link name="left_wheel">
    <collision>
      <origin xyz="0 0 0" rpy="1.57079632679 0 0" />
      <geometry>
        <cylinder radius="0.1" length="0.05" />
      </geometry>
    </collision>
  </link>

  <link name="right_wheel">
    <collision>
      <origin xyz="0 0 0" rpy="1.57079632679 0 0" />
      <geometry>
        <cylinder radius="0.1" length="0.05" />
      </geometry>
    </collision>
  </link>

  <joint name="left_wheel_joint" type="continuous">
    <parent link="base" />
    <child link="left_wheel" />
    <origin xyz="0 0.3 -0.1" rpy="0 0 0" />
    <axis xyz="0 1 0" />
  </joint>

  <joint name="right_wheel_joint" type="continuous">
    <parent link="base" />
    <child link="right_wheel" />
    <origin xyz="0 -0.3 -0.1" rpy="0 0 0" />
    <axis xyz="0 1 0" />
  </joint>
</robot>
